[2025-09-13T05:00:04.262+0000] {local_task_job_runner.py:120} INFO - ::group::Pre task execution logs
[2025-09-13T05:00:04.360+0000] {taskinstance.py:2076} INFO - Dependencies all met for dep_context=non-requeueable deps ti=<TaskInstance: dag_export_es.exportar_sismos manual__2025-09-13T05:00:03.503316+00:00 [queued]>
[2025-09-13T05:00:04.389+0000] {taskinstance.py:2076} INFO - Dependencies all met for dep_context=requeueable deps ti=<TaskInstance: dag_export_es.exportar_sismos manual__2025-09-13T05:00:03.503316+00:00 [queued]>
[2025-09-13T05:00:04.391+0000] {taskinstance.py:2306} INFO - Starting attempt 1 of 1
[2025-09-13T05:00:04.418+0000] {taskinstance.py:2330} INFO - Executing <Task(PythonOperator): exportar_sismos> on 2025-09-13 05:00:03.503316+00:00
[2025-09-13T05:00:04.463+0000] {logging_mixin.py:188} WARNING - /home/***/.local/lib/python3.12/site-packages/***/task/task_runner/standard_task_runner.py:61 DeprecationWarning: This process (pid=221) is multi-threaded, use of fork() may lead to deadlocks in the child.
[2025-09-13T05:00:04.444+0000] {standard_task_runner.py:90} INFO - Running: ['***', 'tasks', 'run', 'dag_export_es', 'exportar_sismos', 'manual__2025-09-13T05:00:03.503316+00:00', '--job-id', '22', '--raw', '--subdir', 'DAGS_FOLDER/dag_export_es.py', '--cfg-path', '/tmp/tmpppycfj88']
[2025-09-13T05:00:04.489+0000] {standard_task_runner.py:91} INFO - Job 22: Subtask exportar_sismos
[2025-09-13T05:00:04.488+0000] {standard_task_runner.py:63} INFO - Started process 222 to run task
[2025-09-13T05:00:04.697+0000] {task_command.py:426} INFO - Running <TaskInstance: dag_export_es.exportar_sismos manual__2025-09-13T05:00:03.503316+00:00 [running]> on host 4044a091ce26
[2025-09-13T05:00:04.780+0000] {taskinstance.py:2648} INFO - Exporting env vars: AIRFLOW_CTX_DAG_OWNER='***' AIRFLOW_CTX_DAG_ID='dag_export_es' AIRFLOW_CTX_TASK_ID='exportar_sismos' AIRFLOW_CTX_EXECUTION_DATE='2025-09-13T05:00:03.503316+00:00' AIRFLOW_CTX_TRY_NUMBER='1' AIRFLOW_CTX_DAG_RUN_ID='manual__2025-09-13T05:00:03.503316+00:00'
[2025-09-13T05:00:04.781+0000] {taskinstance.py:430} INFO - ::endgroup::
[2025-09-13T05:00:04.820+0000] {taskinstance.py:441} INFO - ::group::Post task execution logs
[2025-09-13T05:00:04.854+0000] {taskinstance.py:2905} ERROR - Task failed with exception
Traceback (most recent call last):
  File "/home/airflow/.local/lib/python3.12/site-packages/airflow/models/taskinstance.py", line 465, in _execute_task
    result = _execute_callable(context=context, **execute_callable_kwargs)
             ^^^^^^^^^^^^^^^^^^^^^^^^^^^^^^^^^^^^^^^^^^^^^^^^^^^^^^^^^^^^^
  File "/home/airflow/.local/lib/python3.12/site-packages/airflow/models/taskinstance.py", line 432, in _execute_callable
    return execute_callable(context=context, **execute_callable_kwargs)
           ^^^^^^^^^^^^^^^^^^^^^^^^^^^^^^^^^^^^^^^^^^^^^^^^^^^^^^^^^^^^
  File "/home/airflow/.local/lib/python3.12/site-packages/airflow/models/baseoperator.py", line 400, in wrapper
    return func(self, *args, **kwargs)
           ^^^^^^^^^^^^^^^^^^^^^^^^^^^
  File "/home/airflow/.local/lib/python3.12/site-packages/airflow/operators/python.py", line 235, in execute
    return_value = self.execute_callable()
                   ^^^^^^^^^^^^^^^^^^^^^^^
  File "/home/airflow/.local/lib/python3.12/site-packages/airflow/operators/python.py", line 252, in execute_callable
    return self.python_callable(*self.op_args, **self.op_kwargs)
           ^^^^^^^^^^^^^^^^^^^^^^^^^^^^^^^^^^^^^^^^^^^^^^^^^^^^^
  File "/opt/airflow/dags/dag_export_es.py", line 36, in exportar_sismos
    conn = _pg_conn("pg_cotopaxi"); cur = conn.cursor()
           ^^^^^^^^^^^^^^^^^^^^^^^
  File "/opt/airflow/dags/dag_export_es.py", line 11, in _pg_conn
    c = BaseHook.get_connection(conn_id)
        ^^^^^^^^^^^^^^^^^^^^^^^^^^^^^^^^
  File "/home/airflow/.local/lib/python3.12/site-packages/airflow/hooks/base.py", line 83, in get_connection
    conn = Connection.get_connection_from_secrets(conn_id)
           ^^^^^^^^^^^^^^^^^^^^^^^^^^^^^^^^^^^^^^^^^^^^^^^
  File "/home/airflow/.local/lib/python3.12/site-packages/airflow/models/connection.py", line 519, in get_connection_from_secrets
    raise AirflowNotFoundException(f"The conn_id `{conn_id}` isn't defined")
airflow.exceptions.AirflowNotFoundException: The conn_id `pg_cotopaxi` isn't defined
[2025-09-13T05:00:04.888+0000] {taskinstance.py:1206} INFO - Marking task as FAILED. dag_id=dag_export_es, task_id=exportar_sismos, run_id=manual__2025-09-13T05:00:03.503316+00:00, execution_date=20250913T050003, start_date=20250913T050004, end_date=20250913T050004
[2025-09-13T05:00:04.914+0000] {standard_task_runner.py:110} ERROR - Failed to execute job 22 for task exportar_sismos (The conn_id `pg_cotopaxi` isn't defined; 222)
[2025-09-13T05:00:04.943+0000] {local_task_job_runner.py:240} INFO - Task exited with return code 1
[2025-09-13T05:00:04.966+0000] {taskinstance.py:3498} INFO - 0 downstream tasks scheduled from follow-on schedule check
[2025-09-13T05:00:04.971+0000] {local_task_job_runner.py:222} INFO - ::endgroup::
