[2025-09-13T07:42:37.096+0000] {local_task_job_runner.py:120} INFO - ::group::Pre task execution logs
[2025-09-13T07:42:37.136+0000] {taskinstance.py:2076} INFO - Dependencies all met for dep_context=non-requeueable deps ti=<TaskInstance: dag_3_knime_to_es.ensure_index manual__2025-09-13T07:37:35.218484+00:00 [queued]>
[2025-09-13T07:42:37.141+0000] {taskinstance.py:2076} INFO - Dependencies all met for dep_context=requeueable deps ti=<TaskInstance: dag_3_knime_to_es.ensure_index manual__2025-09-13T07:37:35.218484+00:00 [queued]>
[2025-09-13T07:42:37.141+0000] {taskinstance.py:2306} INFO - Starting attempt 2 of 2
[2025-09-13T07:42:37.147+0000] {taskinstance.py:2330} INFO - Executing <Task(PythonOperator): ensure_index> on 2025-09-13 07:37:35.218484+00:00
[2025-09-13T07:42:37.160+0000] {logging_mixin.py:188} WARNING - /home/***/.local/lib/python3.12/site-packages/***/task/task_runner/standard_task_runner.py:61 DeprecationWarning: This process (pid=528) is multi-threaded, use of fork() may lead to deadlocks in the child.
[2025-09-13T07:42:37.158+0000] {standard_task_runner.py:90} INFO - Running: ['***', 'tasks', 'run', 'dag_3_knime_to_es', 'ensure_index', 'manual__2025-09-13T07:37:35.218484+00:00', '--job-id', '103', '--raw', '--subdir', 'DAGS_FOLDER/dag_3_knime_to_es.py', '--cfg-path', '/tmp/tmpqfzwitlb']
[2025-09-13T07:42:37.161+0000] {standard_task_runner.py:91} INFO - Job 103: Subtask ensure_index
[2025-09-13T07:42:37.161+0000] {standard_task_runner.py:63} INFO - Started process 529 to run task
[2025-09-13T07:42:37.218+0000] {task_command.py:426} INFO - Running <TaskInstance: dag_3_knime_to_es.ensure_index manual__2025-09-13T07:37:35.218484+00:00 [running]> on host c9e5a5421cb6
[2025-09-13T07:42:37.328+0000] {taskinstance.py:2648} INFO - Exporting env vars: AIRFLOW_CTX_DAG_OWNER='***' AIRFLOW_CTX_DAG_ID='dag_3_knime_to_es' AIRFLOW_CTX_TASK_ID='ensure_index' AIRFLOW_CTX_EXECUTION_DATE='2025-09-13T07:37:35.218484+00:00' AIRFLOW_CTX_TRY_NUMBER='2' AIRFLOW_CTX_DAG_RUN_ID='manual__2025-09-13T07:37:35.218484+00:00'
[2025-09-13T07:42:37.330+0000] {taskinstance.py:430} INFO - ::endgroup::
[2025-09-13T07:42:37.393+0000] {taskinstance.py:441} INFO - ::group::Post task execution logs
[2025-09-13T07:42:37.394+0000] {taskinstance.py:2905} ERROR - Task failed with exception
Traceback (most recent call last):
  File "/home/airflow/.local/lib/python3.12/site-packages/urllib3/connection.py", line 198, in _new_conn
    sock = connection.create_connection(
           ^^^^^^^^^^^^^^^^^^^^^^^^^^^^^
  File "/home/airflow/.local/lib/python3.12/site-packages/urllib3/util/connection.py", line 60, in create_connection
    for res in socket.getaddrinfo(host, port, family, socket.SOCK_STREAM):
               ^^^^^^^^^^^^^^^^^^^^^^^^^^^^^^^^^^^^^^^^^^^^^^^^^^^^^^^^^^
  File "/usr/local/lib/python3.12/socket.py", line 963, in getaddrinfo
    for res in _socket.getaddrinfo(host, port, family, type, proto, flags):
               ^^^^^^^^^^^^^^^^^^^^^^^^^^^^^^^^^^^^^^^^^^^^^^^^^^^^^^^^^^^
socket.gaierror: [Errno -2] Name or service not known

The above exception was the direct cause of the following exception:

Traceback (most recent call last):
  File "/home/airflow/.local/lib/python3.12/site-packages/urllib3/connectionpool.py", line 793, in urlopen
    response = self._make_request(
               ^^^^^^^^^^^^^^^^^^^
  File "/home/airflow/.local/lib/python3.12/site-packages/urllib3/connectionpool.py", line 496, in _make_request
    conn.request(
  File "/home/airflow/.local/lib/python3.12/site-packages/urllib3/connection.py", line 400, in request
    self.endheaders()
  File "/usr/local/lib/python3.12/http/client.py", line 1331, in endheaders
    self._send_output(message_body, encode_chunked=encode_chunked)
  File "/usr/local/lib/python3.12/http/client.py", line 1091, in _send_output
    self.send(msg)
  File "/usr/local/lib/python3.12/http/client.py", line 1035, in send
    self.connect()
  File "/home/airflow/.local/lib/python3.12/site-packages/urllib3/connection.py", line 238, in connect
    self.sock = self._new_conn()
                ^^^^^^^^^^^^^^^^
  File "/home/airflow/.local/lib/python3.12/site-packages/urllib3/connection.py", line 205, in _new_conn
    raise NameResolutionError(self.host, self, e) from e
urllib3.exceptions.NameResolutionError: <urllib3.connection.HTTPConnection object at 0xffffa20e01d0>: Failed to resolve 'elasticsearch' ([Errno -2] Name or service not known)

The above exception was the direct cause of the following exception:

Traceback (most recent call last):
  File "/home/airflow/.local/lib/python3.12/site-packages/requests/adapters.py", line 486, in send
    resp = conn.urlopen(
           ^^^^^^^^^^^^^
  File "/home/airflow/.local/lib/python3.12/site-packages/urllib3/connectionpool.py", line 847, in urlopen
    retries = retries.increment(
              ^^^^^^^^^^^^^^^^^^
  File "/home/airflow/.local/lib/python3.12/site-packages/urllib3/util/retry.py", line 515, in increment
    raise MaxRetryError(_pool, url, reason) from reason  # type: ignore[arg-type]
    ^^^^^^^^^^^^^^^^^^^^^^^^^^^^^^^^^^^^^^^^^^^^^^^^^^^
urllib3.exceptions.MaxRetryError: HTTPConnectionPool(host='elasticsearch', port=9200): Max retries exceeded with url: /resultado-vulnerabilidad (Caused by NameResolutionError("<urllib3.connection.HTTPConnection object at 0xffffa20e01d0>: Failed to resolve 'elasticsearch' ([Errno -2] Name or service not known)"))

During handling of the above exception, another exception occurred:

Traceback (most recent call last):
  File "/home/airflow/.local/lib/python3.12/site-packages/airflow/models/taskinstance.py", line 465, in _execute_task
    result = _execute_callable(context=context, **execute_callable_kwargs)
             ^^^^^^^^^^^^^^^^^^^^^^^^^^^^^^^^^^^^^^^^^^^^^^^^^^^^^^^^^^^^^
  File "/home/airflow/.local/lib/python3.12/site-packages/airflow/models/taskinstance.py", line 432, in _execute_callable
    return execute_callable(context=context, **execute_callable_kwargs)
           ^^^^^^^^^^^^^^^^^^^^^^^^^^^^^^^^^^^^^^^^^^^^^^^^^^^^^^^^^^^^
  File "/home/airflow/.local/lib/python3.12/site-packages/airflow/models/baseoperator.py", line 400, in wrapper
    return func(self, *args, **kwargs)
           ^^^^^^^^^^^^^^^^^^^^^^^^^^^
  File "/home/airflow/.local/lib/python3.12/site-packages/airflow/operators/python.py", line 235, in execute
    return_value = self.execute_callable()
                   ^^^^^^^^^^^^^^^^^^^^^^^
  File "/home/airflow/.local/lib/python3.12/site-packages/airflow/operators/python.py", line 252, in execute_callable
    return self.python_callable(*self.op_args, **self.op_kwargs)
           ^^^^^^^^^^^^^^^^^^^^^^^^^^^^^^^^^^^^^^^^^^^^^^^^^^^^^
  File "/opt/airflow/dags/dag_3_knime_to_es.py", line 33, in ensure_index
    r = requests.get(f"{ES_URL}/{ES_INDEX}")
        ^^^^^^^^^^^^^^^^^^^^^^^^^^^^^^^^^^^^
  File "/home/airflow/.local/lib/python3.12/site-packages/requests/api.py", line 73, in get
    return request("get", url, params=params, **kwargs)
           ^^^^^^^^^^^^^^^^^^^^^^^^^^^^^^^^^^^^^^^^^^^^
  File "/home/airflow/.local/lib/python3.12/site-packages/requests/api.py", line 59, in request
    return session.request(method=method, url=url, **kwargs)
           ^^^^^^^^^^^^^^^^^^^^^^^^^^^^^^^^^^^^^^^^^^^^^^^^^
  File "/home/airflow/.local/lib/python3.12/site-packages/requests/sessions.py", line 589, in request
    resp = self.send(prep, **send_kwargs)
           ^^^^^^^^^^^^^^^^^^^^^^^^^^^^^^
  File "/home/airflow/.local/lib/python3.12/site-packages/requests/sessions.py", line 703, in send
    r = adapter.send(request, **kwargs)
        ^^^^^^^^^^^^^^^^^^^^^^^^^^^^^^^
  File "/home/airflow/.local/lib/python3.12/site-packages/requests/adapters.py", line 519, in send
    raise ConnectionError(e, request=request)
requests.exceptions.ConnectionError: HTTPConnectionPool(host='elasticsearch', port=9200): Max retries exceeded with url: /resultado-vulnerabilidad (Caused by NameResolutionError("<urllib3.connection.HTTPConnection object at 0xffffa20e01d0>: Failed to resolve 'elasticsearch' ([Errno -2] Name or service not known)"))
[2025-09-13T07:42:37.423+0000] {taskinstance.py:1206} INFO - Marking task as FAILED. dag_id=dag_3_knime_to_es, task_id=ensure_index, run_id=manual__2025-09-13T07:37:35.218484+00:00, execution_date=20250913T073735, start_date=20250913T074237, end_date=20250913T074237
[2025-09-13T07:42:37.430+0000] {standard_task_runner.py:110} ERROR - Failed to execute job 103 for task ensure_index (HTTPConnectionPool(host='elasticsearch', port=9200): Max retries exceeded with url: /resultado-vulnerabilidad (Caused by NameResolutionError("<urllib3.connection.HTTPConnection object at 0xffffa20e01d0>: Failed to resolve 'elasticsearch' ([Errno -2] Name or service not known)")); 529)
[2025-09-13T07:42:37.471+0000] {local_task_job_runner.py:240} INFO - Task exited with return code 1
[2025-09-13T07:42:37.482+0000] {taskinstance.py:3498} INFO - 0 downstream tasks scheduled from follow-on schedule check
[2025-09-13T07:42:37.484+0000] {local_task_job_runner.py:222} INFO - ::endgroup::
