[2025-09-13T05:53:34.444+0000] {local_task_job_runner.py:120} INFO - ::group::Pre task execution logs
[2025-09-13T05:53:34.484+0000] {taskinstance.py:2076} INFO - Dependencies all met for dep_context=non-requeueable deps ti=<TaskInstance: dag_export_es.exportar_sismos manual__2025-09-13T05:53:33.830673+00:00 [queued]>
[2025-09-13T05:53:34.489+0000] {taskinstance.py:2076} INFO - Dependencies all met for dep_context=requeueable deps ti=<TaskInstance: dag_export_es.exportar_sismos manual__2025-09-13T05:53:33.830673+00:00 [queued]>
[2025-09-13T05:53:34.489+0000] {taskinstance.py:2306} INFO - Starting attempt 1 of 1
[2025-09-13T05:53:34.500+0000] {taskinstance.py:2330} INFO - Executing <Task(PythonOperator): exportar_sismos> on 2025-09-13 05:53:33.830673+00:00
[2025-09-13T05:53:34.506+0000] {standard_task_runner.py:90} INFO - Running: ['***', 'tasks', 'run', 'dag_export_es', 'exportar_sismos', 'manual__2025-09-13T05:53:33.830673+00:00', '--job-id', '58', '--raw', '--subdir', 'DAGS_FOLDER/dag_export_es.py', '--cfg-path', '/tmp/tmp7t4yt57d']
[2025-09-13T05:53:34.510+0000] {standard_task_runner.py:91} INFO - Job 58: Subtask exportar_sismos
[2025-09-13T05:53:34.510+0000] {logging_mixin.py:188} WARNING - /home/***/.local/lib/python3.12/site-packages/***/task/task_runner/standard_task_runner.py:61 DeprecationWarning: This process (pid=349) is multi-threaded, use of fork() may lead to deadlocks in the child.
[2025-09-13T05:53:34.512+0000] {standard_task_runner.py:63} INFO - Started process 350 to run task
[2025-09-13T05:53:34.567+0000] {task_command.py:426} INFO - Running <TaskInstance: dag_export_es.exportar_sismos manual__2025-09-13T05:53:33.830673+00:00 [running]> on host a3e94ed1580d
[2025-09-13T05:53:34.629+0000] {taskinstance.py:2648} INFO - Exporting env vars: AIRFLOW_CTX_DAG_OWNER='***' AIRFLOW_CTX_DAG_ID='dag_export_es' AIRFLOW_CTX_TASK_ID='exportar_sismos' AIRFLOW_CTX_EXECUTION_DATE='2025-09-13T05:53:33.830673+00:00' AIRFLOW_CTX_TRY_NUMBER='1' AIRFLOW_CTX_DAG_RUN_ID='manual__2025-09-13T05:53:33.830673+00:00'
[2025-09-13T05:53:34.630+0000] {taskinstance.py:430} INFO - ::endgroup::
[2025-09-13T05:53:34.664+0000] {base.py:84} INFO - Using connection ID 'pg_cotopaxi' for task execution.
[2025-09-13T05:53:34.692+0000] {taskinstance.py:441} INFO - ::group::Post task execution logs
[2025-09-13T05:53:34.693+0000] {taskinstance.py:2905} ERROR - Task failed with exception
Traceback (most recent call last):
  File "/home/airflow/.local/lib/python3.12/site-packages/urllib3/connection.py", line 198, in _new_conn
    sock = connection.create_connection(
           ^^^^^^^^^^^^^^^^^^^^^^^^^^^^^
  File "/home/airflow/.local/lib/python3.12/site-packages/urllib3/util/connection.py", line 85, in create_connection
    raise err
  File "/home/airflow/.local/lib/python3.12/site-packages/urllib3/util/connection.py", line 73, in create_connection
    sock.connect(sa)
ConnectionRefusedError: [Errno 111] Connection refused

The above exception was the direct cause of the following exception:

Traceback (most recent call last):
  File "/home/airflow/.local/lib/python3.12/site-packages/urllib3/connectionpool.py", line 793, in urlopen
    response = self._make_request(
               ^^^^^^^^^^^^^^^^^^^
  File "/home/airflow/.local/lib/python3.12/site-packages/urllib3/connectionpool.py", line 496, in _make_request
    conn.request(
  File "/home/airflow/.local/lib/python3.12/site-packages/urllib3/connection.py", line 400, in request
    self.endheaders()
  File "/usr/local/lib/python3.12/http/client.py", line 1331, in endheaders
    self._send_output(message_body, encode_chunked=encode_chunked)
  File "/usr/local/lib/python3.12/http/client.py", line 1091, in _send_output
    self.send(msg)
  File "/usr/local/lib/python3.12/http/client.py", line 1035, in send
    self.connect()
  File "/home/airflow/.local/lib/python3.12/site-packages/urllib3/connection.py", line 238, in connect
    self.sock = self._new_conn()
                ^^^^^^^^^^^^^^^^
  File "/home/airflow/.local/lib/python3.12/site-packages/urllib3/connection.py", line 213, in _new_conn
    raise NewConnectionError(
urllib3.exceptions.NewConnectionError: <urllib3.connection.HTTPConnection object at 0xffff7419b4d0>: Failed to establish a new connection: [Errno 111] Connection refused

The above exception was the direct cause of the following exception:

Traceback (most recent call last):
  File "/home/airflow/.local/lib/python3.12/site-packages/requests/adapters.py", line 486, in send
    resp = conn.urlopen(
           ^^^^^^^^^^^^^
  File "/home/airflow/.local/lib/python3.12/site-packages/urllib3/connectionpool.py", line 847, in urlopen
    retries = retries.increment(
              ^^^^^^^^^^^^^^^^^^
  File "/home/airflow/.local/lib/python3.12/site-packages/urllib3/util/retry.py", line 515, in increment
    raise MaxRetryError(_pool, url, reason) from reason  # type: ignore[arg-type]
    ^^^^^^^^^^^^^^^^^^^^^^^^^^^^^^^^^^^^^^^^^^^^^^^^^^^
urllib3.exceptions.MaxRetryError: HTTPConnectionPool(host='host.docker.internal', port=9200): Max retries exceeded with url: /_bulk (Caused by NewConnectionError('<urllib3.connection.HTTPConnection object at 0xffff7419b4d0>: Failed to establish a new connection: [Errno 111] Connection refused'))

During handling of the above exception, another exception occurred:

Traceback (most recent call last):
  File "/home/airflow/.local/lib/python3.12/site-packages/airflow/models/taskinstance.py", line 465, in _execute_task
    result = _execute_callable(context=context, **execute_callable_kwargs)
             ^^^^^^^^^^^^^^^^^^^^^^^^^^^^^^^^^^^^^^^^^^^^^^^^^^^^^^^^^^^^^
  File "/home/airflow/.local/lib/python3.12/site-packages/airflow/models/taskinstance.py", line 432, in _execute_callable
    return execute_callable(context=context, **execute_callable_kwargs)
           ^^^^^^^^^^^^^^^^^^^^^^^^^^^^^^^^^^^^^^^^^^^^^^^^^^^^^^^^^^^^
  File "/home/airflow/.local/lib/python3.12/site-packages/airflow/models/baseoperator.py", line 400, in wrapper
    return func(self, *args, **kwargs)
           ^^^^^^^^^^^^^^^^^^^^^^^^^^^
  File "/home/airflow/.local/lib/python3.12/site-packages/airflow/operators/python.py", line 235, in execute
    return_value = self.execute_callable()
                   ^^^^^^^^^^^^^^^^^^^^^^^
  File "/home/airflow/.local/lib/python3.12/site-packages/airflow/operators/python.py", line 252, in execute_callable
    return self.python_callable(*self.op_args, **self.op_kwargs)
           ^^^^^^^^^^^^^^^^^^^^^^^^^^^^^^^^^^^^^^^^^^^^^^^^^^^^^
  File "/opt/airflow/dags/dag_export_es.py", line 56, in exportar_sismos
    _bulk("rt-seismic", gen(), "id")
  File "/opt/airflow/dags/dag_export_es.py", line 31, in _bulk
    flush()
  File "/opt/airflow/dags/dag_export_es.py", line 22, in flush
    r = requests.post(f"{ES_URL}/_bulk", headers=headers, data=payload, timeout=60)
        ^^^^^^^^^^^^^^^^^^^^^^^^^^^^^^^^^^^^^^^^^^^^^^^^^^^^^^^^^^^^^^^^^^^^^^^^^^^
  File "/home/airflow/.local/lib/python3.12/site-packages/requests/api.py", line 115, in post
    return request("post", url, data=data, json=json, **kwargs)
           ^^^^^^^^^^^^^^^^^^^^^^^^^^^^^^^^^^^^^^^^^^^^^^^^^^^^
  File "/home/airflow/.local/lib/python3.12/site-packages/requests/api.py", line 59, in request
    return session.request(method=method, url=url, **kwargs)
           ^^^^^^^^^^^^^^^^^^^^^^^^^^^^^^^^^^^^^^^^^^^^^^^^^
  File "/home/airflow/.local/lib/python3.12/site-packages/requests/sessions.py", line 589, in request
    resp = self.send(prep, **send_kwargs)
           ^^^^^^^^^^^^^^^^^^^^^^^^^^^^^^
  File "/home/airflow/.local/lib/python3.12/site-packages/requests/sessions.py", line 703, in send
    r = adapter.send(request, **kwargs)
        ^^^^^^^^^^^^^^^^^^^^^^^^^^^^^^^
  File "/home/airflow/.local/lib/python3.12/site-packages/requests/adapters.py", line 519, in send
    raise ConnectionError(e, request=request)
requests.exceptions.ConnectionError: HTTPConnectionPool(host='host.docker.internal', port=9200): Max retries exceeded with url: /_bulk (Caused by NewConnectionError('<urllib3.connection.HTTPConnection object at 0xffff7419b4d0>: Failed to establish a new connection: [Errno 111] Connection refused'))
[2025-09-13T05:53:34.702+0000] {taskinstance.py:1206} INFO - Marking task as FAILED. dag_id=dag_export_es, task_id=exportar_sismos, run_id=manual__2025-09-13T05:53:33.830673+00:00, execution_date=20250913T055333, start_date=20250913T055334, end_date=20250913T055334
[2025-09-13T05:53:34.707+0000] {standard_task_runner.py:110} ERROR - Failed to execute job 58 for task exportar_sismos (HTTPConnectionPool(host='host.docker.internal', port=9200): Max retries exceeded with url: /_bulk (Caused by NewConnectionError('<urllib3.connection.HTTPConnection object at 0xffff7419b4d0>: Failed to establish a new connection: [Errno 111] Connection refused')); 350)
[2025-09-13T05:53:34.739+0000] {local_task_job_runner.py:240} INFO - Task exited with return code 1
[2025-09-13T05:53:34.753+0000] {taskinstance.py:3498} INFO - 0 downstream tasks scheduled from follow-on schedule check
[2025-09-13T05:53:34.755+0000] {local_task_job_runner.py:222} INFO - ::endgroup::
