[2025-09-13T06:00:17.058+0000] {local_task_job_runner.py:120} INFO - ::group::Pre task execution logs
[2025-09-13T06:00:17.085+0000] {taskinstance.py:2076} INFO - Dependencies all met for dep_context=non-requeueable deps ti=<TaskInstance: dag_export_es.exportar_sismos manual__2025-09-13T06:00:16.258851+00:00 [queued]>
[2025-09-13T06:00:17.090+0000] {taskinstance.py:2076} INFO - Dependencies all met for dep_context=requeueable deps ti=<TaskInstance: dag_export_es.exportar_sismos manual__2025-09-13T06:00:16.258851+00:00 [queued]>
[2025-09-13T06:00:17.090+0000] {taskinstance.py:2306} INFO - Starting attempt 1 of 1
[2025-09-13T06:00:17.096+0000] {taskinstance.py:2330} INFO - Executing <Task(PythonOperator): exportar_sismos> on 2025-09-13 06:00:16.258851+00:00
[2025-09-13T06:00:17.109+0000] {standard_task_runner.py:90} INFO - Running: ['***', 'tasks', 'run', 'dag_export_es', 'exportar_sismos', 'manual__2025-09-13T06:00:16.258851+00:00', '--job-id', '71', '--raw', '--subdir', 'DAGS_FOLDER/dag_export_es.py', '--cfg-path', '/tmp/tmp57ng__91']
[2025-09-13T06:00:17.112+0000] {standard_task_runner.py:91} INFO - Job 71: Subtask exportar_sismos
[2025-09-13T06:00:17.112+0000] {logging_mixin.py:188} WARNING - /home/***/.local/lib/python3.12/site-packages/***/task/task_runner/standard_task_runner.py:61 DeprecationWarning: This process (pid=287) is multi-threaded, use of fork() may lead to deadlocks in the child.
[2025-09-13T06:00:17.114+0000] {standard_task_runner.py:63} INFO - Started process 288 to run task
[2025-09-13T06:00:17.150+0000] {task_command.py:426} INFO - Running <TaskInstance: dag_export_es.exportar_sismos manual__2025-09-13T06:00:16.258851+00:00 [running]> on host 1555c6fea04d
[2025-09-13T06:00:17.208+0000] {taskinstance.py:2648} INFO - Exporting env vars: AIRFLOW_CTX_DAG_OWNER='***' AIRFLOW_CTX_DAG_ID='dag_export_es' AIRFLOW_CTX_TASK_ID='exportar_sismos' AIRFLOW_CTX_EXECUTION_DATE='2025-09-13T06:00:16.258851+00:00' AIRFLOW_CTX_TRY_NUMBER='1' AIRFLOW_CTX_DAG_RUN_ID='manual__2025-09-13T06:00:16.258851+00:00'
[2025-09-13T06:00:17.209+0000] {taskinstance.py:430} INFO - ::endgroup::
[2025-09-13T06:00:17.242+0000] {base.py:84} INFO - Using connection ID 'pg_cotopaxi' for task execution.
[2025-09-13T06:00:17.282+0000] {taskinstance.py:441} INFO - ::group::Post task execution logs
[2025-09-13T06:00:17.283+0000] {taskinstance.py:2905} ERROR - Task failed with exception
Traceback (most recent call last):
  File "/home/airflow/.local/lib/python3.12/site-packages/urllib3/connection.py", line 198, in _new_conn
    sock = connection.create_connection(
           ^^^^^^^^^^^^^^^^^^^^^^^^^^^^^
  File "/home/airflow/.local/lib/python3.12/site-packages/urllib3/util/connection.py", line 60, in create_connection
    for res in socket.getaddrinfo(host, port, family, socket.SOCK_STREAM):
               ^^^^^^^^^^^^^^^^^^^^^^^^^^^^^^^^^^^^^^^^^^^^^^^^^^^^^^^^^^
  File "/usr/local/lib/python3.12/socket.py", line 963, in getaddrinfo
    for res in _socket.getaddrinfo(host, port, family, type, proto, flags):
               ^^^^^^^^^^^^^^^^^^^^^^^^^^^^^^^^^^^^^^^^^^^^^^^^^^^^^^^^^^^
socket.gaierror: [Errno -2] Name or service not known

The above exception was the direct cause of the following exception:

Traceback (most recent call last):
  File "/home/airflow/.local/lib/python3.12/site-packages/urllib3/connectionpool.py", line 793, in urlopen
    response = self._make_request(
               ^^^^^^^^^^^^^^^^^^^
  File "/home/airflow/.local/lib/python3.12/site-packages/urllib3/connectionpool.py", line 496, in _make_request
    conn.request(
  File "/home/airflow/.local/lib/python3.12/site-packages/urllib3/connection.py", line 400, in request
    self.endheaders()
  File "/usr/local/lib/python3.12/http/client.py", line 1331, in endheaders
    self._send_output(message_body, encode_chunked=encode_chunked)
  File "/usr/local/lib/python3.12/http/client.py", line 1091, in _send_output
    self.send(msg)
  File "/usr/local/lib/python3.12/http/client.py", line 1035, in send
    self.connect()
  File "/home/airflow/.local/lib/python3.12/site-packages/urllib3/connection.py", line 238, in connect
    self.sock = self._new_conn()
                ^^^^^^^^^^^^^^^^
  File "/home/airflow/.local/lib/python3.12/site-packages/urllib3/connection.py", line 205, in _new_conn
    raise NameResolutionError(self.host, self, e) from e
urllib3.exceptions.NameResolutionError: <urllib3.connection.HTTPConnection object at 0xffff90b8fb60>: Failed to resolve 'elasticsearch' ([Errno -2] Name or service not known)

The above exception was the direct cause of the following exception:

Traceback (most recent call last):
  File "/home/airflow/.local/lib/python3.12/site-packages/requests/adapters.py", line 486, in send
    resp = conn.urlopen(
           ^^^^^^^^^^^^^
  File "/home/airflow/.local/lib/python3.12/site-packages/urllib3/connectionpool.py", line 847, in urlopen
    retries = retries.increment(
              ^^^^^^^^^^^^^^^^^^
  File "/home/airflow/.local/lib/python3.12/site-packages/urllib3/util/retry.py", line 515, in increment
    raise MaxRetryError(_pool, url, reason) from reason  # type: ignore[arg-type]
    ^^^^^^^^^^^^^^^^^^^^^^^^^^^^^^^^^^^^^^^^^^^^^^^^^^^
urllib3.exceptions.MaxRetryError: HTTPConnectionPool(host='elasticsearch', port=9200): Max retries exceeded with url: /_bulk (Caused by NameResolutionError("<urllib3.connection.HTTPConnection object at 0xffff90b8fb60>: Failed to resolve 'elasticsearch' ([Errno -2] Name or service not known)"))

During handling of the above exception, another exception occurred:

Traceback (most recent call last):
  File "/home/airflow/.local/lib/python3.12/site-packages/airflow/models/taskinstance.py", line 465, in _execute_task
    result = _execute_callable(context=context, **execute_callable_kwargs)
             ^^^^^^^^^^^^^^^^^^^^^^^^^^^^^^^^^^^^^^^^^^^^^^^^^^^^^^^^^^^^^
  File "/home/airflow/.local/lib/python3.12/site-packages/airflow/models/taskinstance.py", line 432, in _execute_callable
    return execute_callable(context=context, **execute_callable_kwargs)
           ^^^^^^^^^^^^^^^^^^^^^^^^^^^^^^^^^^^^^^^^^^^^^^^^^^^^^^^^^^^^
  File "/home/airflow/.local/lib/python3.12/site-packages/airflow/models/baseoperator.py", line 400, in wrapper
    return func(self, *args, **kwargs)
           ^^^^^^^^^^^^^^^^^^^^^^^^^^^
  File "/home/airflow/.local/lib/python3.12/site-packages/airflow/operators/python.py", line 235, in execute
    return_value = self.execute_callable()
                   ^^^^^^^^^^^^^^^^^^^^^^^
  File "/home/airflow/.local/lib/python3.12/site-packages/airflow/operators/python.py", line 252, in execute_callable
    return self.python_callable(*self.op_args, **self.op_kwargs)
           ^^^^^^^^^^^^^^^^^^^^^^^^^^^^^^^^^^^^^^^^^^^^^^^^^^^^^
  File "/opt/airflow/dags/dag_export_es.py", line 58, in exportar_sismos
    _bulk("rt-seismic", gen(), "id")
  File "/opt/airflow/dags/dag_export_es.py", line 33, in _bulk
    flush()
  File "/opt/airflow/dags/dag_export_es.py", line 24, in flush
    r = requests.post(f"{ES_URL}/_bulk", headers=headers, data=payload, timeout=60)
        ^^^^^^^^^^^^^^^^^^^^^^^^^^^^^^^^^^^^^^^^^^^^^^^^^^^^^^^^^^^^^^^^^^^^^^^^^^^
  File "/home/airflow/.local/lib/python3.12/site-packages/requests/api.py", line 115, in post
    return request("post", url, data=data, json=json, **kwargs)
           ^^^^^^^^^^^^^^^^^^^^^^^^^^^^^^^^^^^^^^^^^^^^^^^^^^^^
  File "/home/airflow/.local/lib/python3.12/site-packages/requests/api.py", line 59, in request
    return session.request(method=method, url=url, **kwargs)
           ^^^^^^^^^^^^^^^^^^^^^^^^^^^^^^^^^^^^^^^^^^^^^^^^^
  File "/home/airflow/.local/lib/python3.12/site-packages/requests/sessions.py", line 589, in request
    resp = self.send(prep, **send_kwargs)
           ^^^^^^^^^^^^^^^^^^^^^^^^^^^^^^
  File "/home/airflow/.local/lib/python3.12/site-packages/requests/sessions.py", line 703, in send
    r = adapter.send(request, **kwargs)
        ^^^^^^^^^^^^^^^^^^^^^^^^^^^^^^^
  File "/home/airflow/.local/lib/python3.12/site-packages/requests/adapters.py", line 519, in send
    raise ConnectionError(e, request=request)
requests.exceptions.ConnectionError: HTTPConnectionPool(host='elasticsearch', port=9200): Max retries exceeded with url: /_bulk (Caused by NameResolutionError("<urllib3.connection.HTTPConnection object at 0xffff90b8fb60>: Failed to resolve 'elasticsearch' ([Errno -2] Name or service not known)"))
[2025-09-13T06:00:17.294+0000] {taskinstance.py:1206} INFO - Marking task as FAILED. dag_id=dag_export_es, task_id=exportar_sismos, run_id=manual__2025-09-13T06:00:16.258851+00:00, execution_date=20250913T060016, start_date=20250913T060017, end_date=20250913T060017
[2025-09-13T06:00:17.301+0000] {standard_task_runner.py:110} ERROR - Failed to execute job 71 for task exportar_sismos (HTTPConnectionPool(host='elasticsearch', port=9200): Max retries exceeded with url: /_bulk (Caused by NameResolutionError("<urllib3.connection.HTTPConnection object at 0xffff90b8fb60>: Failed to resolve 'elasticsearch' ([Errno -2] Name or service not known)")); 288)
[2025-09-13T06:00:17.343+0000] {local_task_job_runner.py:240} INFO - Task exited with return code 1
[2025-09-13T06:00:17.359+0000] {taskinstance.py:3498} INFO - 0 downstream tasks scheduled from follow-on schedule check
[2025-09-13T06:00:17.362+0000] {local_task_job_runner.py:222} INFO - ::endgroup::
