[2025-09-13T07:23:36.239+0000] {local_task_job_runner.py:120} INFO - ::group::Pre task execution logs
[2025-09-13T07:23:36.386+0000] {taskinstance.py:2076} INFO - Dependencies all met for dep_context=non-requeueable deps ti=<TaskInstance: dag_1_postgres_pipeline.extract_postgres manual__2025-09-13T07:23:35.073913+00:00 [queued]>
[2025-09-13T07:23:36.423+0000] {taskinstance.py:2076} INFO - Dependencies all met for dep_context=requeueable deps ti=<TaskInstance: dag_1_postgres_pipeline.extract_postgres manual__2025-09-13T07:23:35.073913+00:00 [queued]>
[2025-09-13T07:23:36.424+0000] {taskinstance.py:2306} INFO - Starting attempt 1 of 2
[2025-09-13T07:23:36.452+0000] {taskinstance.py:2330} INFO - Executing <Task(PythonOperator): extract_postgres> on 2025-09-13 07:23:35.073913+00:00
[2025-09-13T07:23:36.479+0000] {standard_task_runner.py:90} INFO - Running: ['***', 'tasks', 'run', 'dag_1_postgres_pipeline', 'extract_postgres', 'manual__2025-09-13T07:23:35.073913+00:00', '--job-id', '99', '--raw', '--subdir', 'DAGS_FOLDER/dag_1_postgres_pipeline.py', '--cfg-path', '/tmp/tmp2ofl6fih']
[2025-09-13T07:23:36.495+0000] {standard_task_runner.py:91} INFO - Job 99: Subtask extract_postgres
[2025-09-13T07:23:36.499+0000] {logging_mixin.py:188} WARNING - /home/***/.local/lib/python3.12/site-packages/***/task/task_runner/standard_task_runner.py:61 DeprecationWarning: This process (pid=738) is multi-threaded, use of fork() may lead to deadlocks in the child.
[2025-09-13T07:23:36.500+0000] {standard_task_runner.py:63} INFO - Started process 739 to run task
[2025-09-13T07:23:36.599+0000] {task_command.py:426} INFO - Running <TaskInstance: dag_1_postgres_pipeline.extract_postgres manual__2025-09-13T07:23:35.073913+00:00 [running]> on host c9e5a5421cb6
[2025-09-13T07:23:36.753+0000] {taskinstance.py:2648} INFO - Exporting env vars: AIRFLOW_CTX_DAG_OWNER='***' AIRFLOW_CTX_DAG_ID='dag_1_postgres_pipeline' AIRFLOW_CTX_TASK_ID='extract_postgres' AIRFLOW_CTX_EXECUTION_DATE='2025-09-13T07:23:35.073913+00:00' AIRFLOW_CTX_TRY_NUMBER='1' AIRFLOW_CTX_DAG_RUN_ID='manual__2025-09-13T07:23:35.073913+00:00'
[2025-09-13T07:23:36.757+0000] {taskinstance.py:430} INFO - ::endgroup::
[2025-09-13T07:23:36.908+0000] {base.py:84} INFO - Using connection ID 'pg_cotopaxi' for task execution.
[2025-09-13T07:23:36.959+0000] {sql.py:470} INFO - Running statement: 
        SELECT row_id,
               canton_id,
               proximidad_volcan_km,
               jefatura_femenina,
               adultos_mayores,
               vulnerabilidad_score,
               COALESCE(updated_at, NOW()) AS updated_at
        FROM vuln_households
        LIMIT 50000;
    , parameters: None
[2025-09-13T07:23:36.965+0000] {taskinstance.py:441} INFO - ::group::Post task execution logs
[2025-09-13T07:23:36.967+0000] {taskinstance.py:2905} ERROR - Task failed with exception
Traceback (most recent call last):
  File "/home/airflow/.local/lib/python3.12/site-packages/airflow/models/taskinstance.py", line 465, in _execute_task
    result = _execute_callable(context=context, **execute_callable_kwargs)
             ^^^^^^^^^^^^^^^^^^^^^^^^^^^^^^^^^^^^^^^^^^^^^^^^^^^^^^^^^^^^^
  File "/home/airflow/.local/lib/python3.12/site-packages/airflow/models/taskinstance.py", line 432, in _execute_callable
    return execute_callable(context=context, **execute_callable_kwargs)
           ^^^^^^^^^^^^^^^^^^^^^^^^^^^^^^^^^^^^^^^^^^^^^^^^^^^^^^^^^^^^
  File "/home/airflow/.local/lib/python3.12/site-packages/airflow/models/baseoperator.py", line 400, in wrapper
    return func(self, *args, **kwargs)
           ^^^^^^^^^^^^^^^^^^^^^^^^^^^
  File "/home/airflow/.local/lib/python3.12/site-packages/airflow/operators/python.py", line 235, in execute
    return_value = self.execute_callable()
                   ^^^^^^^^^^^^^^^^^^^^^^^
  File "/home/airflow/.local/lib/python3.12/site-packages/airflow/operators/python.py", line 252, in execute_callable
    return self.python_callable(*self.op_args, **self.op_kwargs)
           ^^^^^^^^^^^^^^^^^^^^^^^^^^^^^^^^^^^^^^^^^^^^^^^^^^^^^
  File "/opt/airflow/dags/dag_1_postgres_pipeline.py", line 47, in _extract_from_postgres
    rows = hook.get_records(sql)
           ^^^^^^^^^^^^^^^^^^^^^
  File "/home/airflow/.local/lib/python3.12/site-packages/airflow/providers/common/sql/hooks/sql.py", line 283, in get_records
    return self.run(sql=sql, parameters=parameters, handler=fetch_all_handler)
           ^^^^^^^^^^^^^^^^^^^^^^^^^^^^^^^^^^^^^^^^^^^^^^^^^^^^^^^^^^^^^^^^^^^
  File "/home/airflow/.local/lib/python3.12/site-packages/airflow/providers/common/sql/hooks/sql.py", line 418, in run
    self._run_command(cur, sql_statement, parameters)
  File "/home/airflow/.local/lib/python3.12/site-packages/airflow/providers/common/sql/hooks/sql.py", line 475, in _run_command
    cur.execute(sql_statement)
psycopg2.errors.UndefinedTable: relation "vuln_households" does not exist
LINE 9:         FROM vuln_households
                     ^

[2025-09-13T07:23:36.989+0000] {taskinstance.py:1206} INFO - Marking task as UP_FOR_RETRY. dag_id=dag_1_***_pipeline, task_id=extract_***, run_id=manual__2025-09-13T07:23:35.073913+00:00, execution_date=20250913T072335, start_date=20250913T072336, end_date=20250913T072336
[2025-09-13T07:23:36.998+0000] {standard_task_runner.py:110} ERROR - Failed to execute job 99 for task extract_*** (relation "vuln_households" does not exist
LINE 9:         FROM vuln_households
                     ^
; 739)
[2025-09-13T07:23:37.031+0000] {local_task_job_runner.py:240} INFO - Task exited with return code 1
[2025-09-13T07:23:37.061+0000] {taskinstance.py:3498} INFO - 0 downstream tasks scheduled from follow-on schedule check
[2025-09-13T07:23:37.062+0000] {local_task_job_runner.py:222} INFO - ::endgroup::
